Workbook

Sheet HC
A1: A. DATOS DEL ESTABLECIMIENTO Y USARIO / PACIENTE
A2: INSTITUCIÓN DEL SISTEMA | N2: UNICÓDIGO | T2: ESTABLECIMIENTO DE SALUD | AH2: NÚMERO DE HISTORIA CLÍNICA ÚNICA | AZ2: FECHA DE NACIMIENTO | BJ2: No. HOJA
A3: RPC | N3: 56398 | T3: MEDISUPORT / QMC | AH3: 1704289899 | AZ3: 20346 | BJ3: 1
A4: PRIMER APELLIDO | O4: SEGUNDO APELLIDO | AC4: PRIMER NOMBRE | AQ4: SEGUNDO NOMBRE | BE4: SEXO | BI4: EDAD (Años)
A5: AMENDAÑO | O5: COLLAGUAZO | AC5: LUZ | AQ5: EDELINA | BE5: F | BI5: =DATEDIF(AZ3,TODAY(),"Y") -> 71
A6: NUMERO DE TELEFONO Y LUGAR DE RESIDENCIA ACTUAL DEL PACIENTE
A7: NO. CELULAR | O7: PROVINCIA | AH7: CANTON | BA7: PARROQUIA
A8: 0994085197 | O8: PICHINCHA | AH8: QUITO
A10: B. MOTIVO DE CONSULTA | AK10: PRIMERA | AW10: SUBSECUENTE
A13: C. ANTECEDENTES PATOLÓGICOS PERSONALES | AO13: DATOS CLÍNICO - QUIRÚRGICOS, OBSTÉTRICOS, ALÉRGICOS RELEVANTES
A14: 1. CARDIOPATÍA | H14: 2. HIPERTENSIÓN | O14: 3. ENF. C. VASCULAR | U14: 4. ENDÓCRINO METABÓLICO | AB14: 5. CÁNCER | AH14: 6. TUBERCULOSIS | AP14: 7. ENF. MENTAL | AU14: 8. ENF. INFECCIOSA | BA14: 9. MAL FORMACIÓN | BG14: 10. OTRO | BK14: X
A16: LAMICTAL DE 100 MG, 250 MG DIARIOS
A17: D. ANTECEDENTES PATOLÓGICOS FAMILIARES
A18: 1. CARDIOPATÍA | H18: 2. HIPERTENSIÓN | O18: 3. ENF. C. VASCULAR | U18: 4. ENDÓCRINO METABÓLICO | AB18: 5. CÁNCER | AH18: 6. TUBERCULOSIS | AP18: 7. ENF. MENTAL | AU18: 8. ENF. INFECCIOSA | BA18: 9. MAL FORMACIÓN | BG18: 10. OTRO
A23: E. ENFERMEDAD O PROBLEMA ACTUAL | AN23: CRONOLOGÍA - LOCALIZACIÓN - CARACTERÍSTICAS - INTENSIDAD - FRECUENCIA - FACTORES AGRAVANTES
A25: F. CONSTANTES VITALES Y ANTROPOMETRÍA
A26: FECHA | F26: HORA | K26: Temperatura (°C) | O26: Presión Arterial (mmHg) | T26: Pulso / min | Y26: Frecuencia Respiratoria /min | AD26: Peso (Kg) | AI26: Talla (cm) | AN26: IMC (Kg / m 2) | AS26: Perímetro Abdominal (cm) | AX26: Hemoglobina capilar (g/dl) | BC26: Glucosa capilar (mg/ dl) | BH26: Pulsioximetría (%)
A27: =TODAY() -> 46297 | F27: =NOW() -> 46297.855
A30: G. REVISIÓN ACTUAL DE ÓRGANOS Y SISTEMAS | AJ30: MARCAR "X" CUANDO PRESENTE PATOLOGÍA Y DESCRIBA
A31: 1 | B31: PIEL - ANEXOS | M31: 3 | N31: RESPIRATORIO | Z31: 5 | AA31: DIGESTIVO | AL31: 7 | AM31: MÚSCULO - ESQUELÉTICO | AZ31: X | BA31: HEMO - LINFÁTICO
A32: 2 | B32: ÓRGANOS DE LOS SENTIDOS | M32: 4 | N32: CARDIO - VASCULAR | Z32: 6 | AA32: GENITO - URINARIO | AL32: 8 | AM32: ENDOCRINO | AZ32: 10 | BA32: NERVIOSO
A35: SNS-MSP / HCU-form.002 / 2021 | V35: CONSULTA EXTERNA - ANAMNESIS (1)
A37: H. EXAMEN FISICO | AN37: MARCAR "X" CUANDO PRESENTE PATOLOGÍA Y DESCRIBA
A38: REGIONAL | AL38: SISTÉMICO
A39: 1R | C39: PIEL - FANERAS | M39: 6R | O39: BOCA | Y39: 11R | AA39: ABDOMEN | AL39: 1S | AN39: ÓRGANOS DE LOS SENTIDOS | AX39: 6S | AZ39: URINARIO
A40: 2R | C40: CABEZA | M40: 7R | O40: OROFARINGE | Y40: 12R | AA40: COLUMNA VERTEBRAL | AL40: 2S | AN40: RESPIRATORIO | AX40: 7S | AZ40: MÚSCULO - ESQUELÉTICO
A41: 3R | C41: OJOS | M41: 8R | O41: CUELLO | Y41: 13R | AA41: INGLE-PERINÉ | AL41: 3S | AN41: CARDIO - VASCULAR | AX41: 8S | AZ41: ENDÓCRINO
A42: 4R | C42: OÍDOS | M42: 9R | O42: AXILAS - MAMAS | Y42: 14R | AA42: MIEMBROS SUPERIORES | AL42: 4S | AN42: DIGESTIVO | AX42: 9S | AZ42: HEMO - LINFÁTICO
A43: 5R | C43: NARIZ | M43: 10R | O43: TÓRAX | Y43: 15R | AA43: MIEMBROS INFERIORES | AL43: 5S | AN43: GENITAL | AX43: 10S | AZ43: NEUROLÓ+A43:BL48GICO
A46: I. DIAGNÓSTICO | R46: PRE= PRESUNTIVO DEF= DEFINITIVO | Y46: CIE | AC46: PRE | AE46: DEF | BE46: CIE | BI46: PRE | BK46: DEF
A47: 1. | AG47: 4.
A48: 2. | AG48: 5.
A49: 3. | AG49: 6.
A51: J. PLAN DE TRATAMIENTO | AR51: DIAGNOSTICO, TERAPÉUTICO Y EDUCACIONAL
A57: TIEMPO APROXIMADO DE CONSULTA: 30 MIN
A59: K. DATOS DEL PROFESIONAL RESPONSABLE
A60: FECHA (aaaa-mm-dd) | I60: HORA (hh:mm) | O60: PRIMER NOMBRE | AH60: PRIMER APELLIDO | AY60: SEGUNDO APELLIDO
A61: =TODAY() -> 46297 | I61: =NOW() -> 46297.855 | O61: FRANK | AH61: MEDINA | AY61: ALI
A62: NÚMERO DE DOCUMENTO DE IDENTIFICACIÓN | O62: FIRMA | AL62: SELLO
A63: 1756930234
...

Sheet INTER007
A1: A. DATOS DEL ESTABLECIMIENTO Y USUARIO / PACIENTE
A2: INSTITUCIÓN DEL SISTEMA | N2: UNICÓDIGO | T2: ESTABLECIMIENTO DE SALUD | AH2: NÚMERO DE HISTORIA CLÍNICA ÚNICA | AZ2: NÚMERO DE ARCHIVO | BK2: No. HOJA
A3: =(HC!A3) -> RPC | N3: 56398 | T3: =+HC!T3 -> MEDISUPORT / QMC | AH3: =HC!AH3 -> 1704289899 | AZ3: =+AH3 -> 1704289899 | BK3: 2
A4: PRIMER APELLIDO | R4: SEGUNDO APELLIDO | AF4: PRIMER NOMBRE | AP4: SEGUNDO NOMBRE | BA4: SEXO | BD4: EDAD | BH4: CONDICIÓN EDAD (MARCAR)
BH5: H | BJ5: D | BL5: M | BN5: A
A6: =(HC!A5) -> AMENDAÑO | R6: =(HC!O5) -> COLLAGUAZO | AF6: =(HC!AC5) -> LUZ | AP6: =(HC!AQ5) -> EDELINA | BA6: =(HC!BE5) -> F | BD6: =SUM(HC!BI5) -> 71 | BN6: X
A8: B. CARACTERÍSTICA DE LA SOLICITUD, MOTIVO Y PRIORIDAD DE ATENCIÓN
A9: SERVICIO | Y9: ESPECIALIDAD | AR9: No. CAMA | AX9: No. SALA | BH9: URGENTE
A10: EMERGENCIA | I10: CONSULTA EXTERNA | N10: X | P10: HOSPITALIZACIÓN | Y10: ENDOCRINOLOGIA | BH10: SI | BL10: NO | BN10: X
A11: ESPECIALIDAD CONSULTADA
A12: DESCRIPCIÓN DEL MOTIVO
A16: C. CUADRO CLÍNICO ACTUAL | AA16: REGISTRAR DE MANERA OBLIGATORIA
A17: =+HC!A24 -> 0
A20: D. RESULTADOS DE EXÁMENES Y PROCEDIMIENTOS DIAGNÓSTICOS RELEVANTES
A30: E. DIAGNÓSTICO | R30: PRE= PRESUNTIVO DEF= DEFINITIVO | AA30: CIE | AE30: PRE | AG30: DEF | BH30: CIE | BL30: PRE | BN30: DEF
A31: 1. | B31: =IF(HC!B47=0," ",HC!B47) | AA31: =IF(HC!Y47=0," ",HC!Y47) | AE31: =IF(HC!AC47=0," ",HC!AC47) | AG31: =IF(HC!AE47=0," ",HC!AE47) | AI31: 4. | AJ31: =IF(+HC!AH47="","",HC!AH47) | BH31: =IF(HC!BE47="","",HC!BE47) | BL31: =IF(HC!BI47=0," ",HC!BI47) | BN31: =IF(HC!BK47=0," ",HC!BK47)
A32: 2. | B32: =IF(HC!B48=0," ",HC!B48) | AA32: =IF(HC!Y48=0," ",HC!Y48) | AE32: =IF(HC!AC48=0," ",HC!AC48) | AG32: =IF(HC!AE48=0," ",HC!AE48) | AI32: 5. | AJ32: =IF(+HC!AH48="","",HC!AH48) | BH32: =IF(HC!BE48="","",HC!BE48) | BL32: =IF(HC!BI48=0," ",HC!BI48) | BN32: =IF(HC!BK48=0," ",HC!BK48)
A33: 3. | B33: =IF(HC!B49=0," ",HC!B49) | AA33: =IF(HC!Y49=0," ",HC!Y49) | AE33: =IF(HC!AC49=0," ",HC!AC49) | AG33: =IF(HC!AE49=0," ",HC!AE49) | AI33: 6. | AJ33: =IF(+HC!AH49="","",HC!AH49) | BH33: =IF(HC!BE49="","",HC!BE49) | BL33: =IF(HC!BI49=0," ",HC!BI49) | BN33: =IF(HC!BK49=0," ",HC!BK49)
A35: F. PLAN TERAPEÚTICO REALIZADO
A49: G. DATOS DEL PROFESIONAL RESPONSABLE
A50: FECHA (aaaa-mm-dd) | I50: HORA (hh:mm) | O50: PRIMER NOMBRE | AI50: PRIMER APELLIDO | BA50: SEGUNDO APELLIDO
A51: =+TODAY() -> 46297 | I51: =+NOW() -> 46297.855 | O51: =+HC!O61 -> FRANK | AI51: =+HC!AH61 -> MEDINA | BA51: =+HC!AY61 -> ALI
A52: NÚMERO DE DOCUMENTO DE IDENTIFICACIÓN | O52: FIRMA | AN52: SELLO
A53: =+HC!A63 -> 1756930234
A55: SNS-MSP/HCU-form.007/2021 | AG55: INTERCONSULTA - SOLICITUD

Sheet REF053
A1: A. DATOS DEL ESTABLECIMIENTO DE ORIGEN Y USUARIO / PACIENTE
A2: INSTITUCIÓN DEL SISTEMA | S2: UNICÓDIGO | Y2: ESTABLECIMIENTO DE SALUD | AO2: TIPOLOGIA | AU2: NÚMERO DE HISTORIA CLÍNICA ÚNICA | BM2: NÚMERO DE ARCHIVO
A3: =(HC!A3) -> RPC | S3: 56398 | Y3: =+HC!T3 -> MEDISUPORT / QMC | AO3: ll | AU3: =+HC!AH3 -> 1704289899 | BM3: =+AU3 -> 1704289899
A4: PRIMER APELLIDO | R4: SEGUNDO APELLIDO | AG4: PRIMER NOMBRE | AS4: SEGUNDO NOMBRE | BF4: SEXO | BI4: FECHA NACIMIENTO | BP4: EDAD | BT4: CONDICIÓN EDAD (MARCAR)
BT5: H | BV5: D | BX5: M | BZ5: A
A6: =(HC!A5) -> AMENDAÑO | R6: =(HC!O5) -> COLLAGUAZO | AG6: =(HC!AC5) -> LUZ | AS6: =(HC!AQ5) -> EDELINA | BF6: =(HC!BE5) -> F | BI6: =SUM(HC!AZ3:BI3) -> 20346 | BP6: =SUM(HC!BI5:BL5) -> 71 | BZ6: X
A7: No. TELÉFONO (CELULAR O CONVENCIONAL) | AN7: REFERENCIA | AU7: X | BA7: DERIVACIÓN
A8: =(HC!A8) -> 0994085197 | AJ8: MOTIVO
AJ9: 1. Accesibilidad geográfica. | BD9: 6. Problemas de abastecimiento.
A10: LUGAR DE RESIDENCIA ACTUAL | AJ10: 2. Falta de espacio físico. | BD10: 7. Insuficiencia de profesionales.
A11: PROVINCIA | M11: CANTÓN | X11: PARROQUIA | AJ11: 3. Falta de equipamiento. | BD11: 8. Inadecuada capacidad resolutiva | BY11: X
A12: =(HC!O8) -> PICHINCHA | M12: =(HC!AH8) -> QUITO | X12: =(HC!BA8) -> 0 | AJ12: 4. Equipos en mal estado. | BD12: 9. Ausencia de la prestación en la cartera de servicios
AJ13: 5. Problemas de infraestructura.
A15: B. DATOS DEL ESTABLECIMIENTO AL QUE SE REFIERE - DERIVA
A16: INSTITUCIÓN DEL SISTEMA | S16: ESTABLECIMIENTO DE SALUD | AM16: SERVICIO | BF16: ESPECIALIDAD
AM17: CONSULTA EXTERNA
A19: C. RESUMEN DEL CUADRO CLÍNICO
A20: =+HC!A24:BL24 -> 0
A23: D. HALLAZGOS RELEVANTES DE EXÁMENES Y PROCEDIMIENTOS DIAGNÓSTICOS
A28: E. DIAGNÓSTICO | U28: PRE= PRESUNTIVO DEF= DEFINITIVO | AE28: CIE | AJ28: PRE | AL28: DEF | BT28: CIE | BX28: PRE | BZ28: DEF
A29: 1. | B29: =IF(HC!B47="","",HC!B47) | AE29: =IF(HC!Y47="","",HC!Y47) | AJ29: =IF(HC!AC47=0," ",HC!AC47) | AL29: =IF(HC!AE47=0," ",HC!AE47) | AN29: 4. | AO29: =+IF(HC!AH47="","",HC!AH47) | BT29: =IF(HC!BE47="","",HC!BE47) | BX29: =IF(HC!BI47=0," ",HC!BI47) | BZ29: =IF(HC!BK47=0," ",HC!BK47)
A30: 2. | B30: =IF(HC!B48="","",HC!B48) | AE30: =IF(HC!Y48="","",HC!Y48) | AJ30: =IF(HC!AC48=0," ",HC!AC48) | AL30: =IF(HC!AE48=0," ",HC!AE48) | AN30: 5. | AO30: =IF(HC!AH48="","",HC!AH48) | BT30: =IF(HC!BE48="","",HC!BE48) | BX30: =IF(HC!BI48=0," ",HC!BI48) | BZ30: =IF(HC!BK48=0," ",HC!BK48)
A31: 3. | B31: =IF(HC!B49="","",HC!B49) | AE31: =IF(HC!Y49="","",HC!Y49) | AJ31: =IF(HC!AC49=0," ",HC!AC49) | AL31: =IF(HC!AE49=0," ",HC!AE49) | AN31: 6. | AO31: =IF(HC!AH49="","",HC!AH49) | BT31: =IF(HC!BE49="","",HC!BE49) | BX31: =IF(HC!BI49=0," ",HC!BI49) | BZ31: =IF(HC!BK49=0," ",HC!BK49)
A33: F. DATOS DEL PROFESIONAL RESPONSABLE
A34: FECHA (aaaa-mm-dd) | K34: HORA (hh:mm) | S34: PRIMER NOMBRE | AO34: PRIMER APELLIDO | BJ34: SEGUNDO APELLIDO
A35: =+TODAY() -> 46297 | K35: =+NOW() -> 46297.855 | S35: =+HC!O61 -> FRANK | AO35: =+HC!AH61 -> MEDINA | BJ35: =+HC!AY61 -> ALI
A36: NÚMERO DE DOCUMENTO DE IDENTIFICACIÓN | S36: FIRMA | AT36: SELLO
A37: =+HC!A63 -> 1756930234
A40: SNS-MSP/HCU-form.053/2021 | AC40: REFERENCIA - DERIVACIÓN- CONTRAREFERENCIA - REFERENCIA INVERSA

Sheet LAB010
A1: A. DATOS DEL ESTABLECIMIENTO Y USUARIO / PACIENTE
A2: INSTITUCIÓN DEL SISTEMA | R2: UNICÓDIGO | X2: ESTABLECIMIENTO DE SALUD | AT2: NÚMERO DE HISTORIA CLÍNICA ÚNICA | BL2: NÚMERO DE ARCHIVO
A3: =(HC!A3) -> RPC | R3: 56398 | X3: =+HC!T3 -> MEDISUPORT / QMC | AT3: =+HC!AH3 -> 1704289899 | BL3: =+AT3 -> 1704289899
A4: PRIMER APELLIDO | P4: SEGUNDO APELLIDO | AD4: PRIMER NOMBRE | AQ4: SEGUNDO NOMBRE | BC4: SEXO | BF4: FECHA NACIMIENTO | BL4: EDAD | BO4: CONDICIÓN EDAD (MARCAR)
BO5: H | BQ5: D | BS5: M | BU5: A
A6: =(HC!A5) -> AMENDAÑO | P6: =(HC!O5) -> COLLAGUAZO | AD6: =(HC!AC5) -> LUZ | AQ6: =(HC!AQ5) -> EDELINA | BC6: =+HC!BE5 -> F | BF6: =SUM(REF053!BI6) -> 20346 | BL6: =SUM(HC!BI5:BL5) -> 71 | BU6: X
A8: B. SERVICIO Y PRIORIDAD DE ATENCIÓN
A9: DIAGNÓSTICO | AG9: CIE | AK9: SERVICIO | AP9: EMERGENCIA | AY9: ESPECIALIDAD | BF9: ENDOCRINOLOGIA | BQ9: PRIORIDAD
A10: 1. | B10: =IF(HC!B47=0," ",HC!B47) | AG10: =IF(HC!Y47=0," ",HC!Y47) | AP10: CONSULTA EXTERNA | AW10: X | AY10: SALA | BQ10: URGENTE
A11: 2. | B11: =IF(HC!B48=0," ",HC!B48) | AG11: =IF(HC!Y48=0," ",HC!Y48) | AP11: HOSPITALIZACIÓN | AY11: CAMA | BQ11: RUTINA
A12: TRATAMIENTO TERAPEUTICO (ESPECIFIQUE NOMBRE Y TIEMPO DE ADMINISTRACIÓN):
A15: C. LISTADO DE EXÁMENES
A16: HEMATOLOGÍA | AB16: COAGULACIÓN Y HEMOSTASIA | AU16: QUÍMICA SANGUÍNEA
A17: BIOMETRIA HEMÁTICA | L17: X | N17: FRAGILIDAD OSMÓTICA ERITROCITARIA | AB17: TIEMPO DE PROTROMBINA (TP) | AU17: GLUCOSA BASAL | BI17: X | BK17: BILIRRUBINA DIRECTA
A18: HEMATOCRITO (HCTO) | N18: METABISULFITO | AB18: TIEMPO DE TROMBOPLASTINA PARCIAL (TTP) | AU18: GLUCOSA POST PRANDIAL 2 HORAS | BI18: X | BK18: BILIRRUBINA INDIRECTA
A19: HEMOGLOBINA (HB) | N19: HEMATOZOOARIO | AB19: TIEMPO DE TROMBINA (TT) | AU19: GLUCOSA AL AZAR | BK19: COLESTEROL TOTAL | BU19: X
A20: PLAQUETAS | N20: INVESTIGACIÓN DE LEISHMANIA | AB20: INR | AU20: SOBRECARGA GLUCOSA 75 gramos | BK20: LIPOPROTEÍNA DE ALTA DENSIDAD (HDL) | BU20: X
A21: RETICULOCITOS | N21: EOSINÓFILO EN MOCO NASAL | AB21: FACTOR COAGULACIÓN VIII | AU21: TEST DE SULLIVAN (GLUCOSA 50 gramos) | BK21: LIPOPROTEÍNA DE BAJA DENSIDAD (LDL) | BU21: X
A22: VELOCIDAD DE ERITROSEDIMENTACIÓN | N22: FROTIS SANGRE PERIFERICA | AB22: FACTOR COAGULACIÓN IX | AU22: UREA | BI22: X | BK22: LIPOPROTEÍNA DE MUY BAJA DENSIDAD (VLDL)
A23: HIERRO SERICO | N23: ÁCIDO FÓLICO | AB23: FACTOR VON WILLEBRAND | AU23: CREATININA | BI23: X | BK23: TRIGLICERIDOS
A24: FIJACIÓN HIERRO | N24: VITAMINA B12 | AB24: FIBRINOGENO | AU24: ACIDO ÚRICO | BI24: X | BK24: ALBUMINA
A25: PORCENTAJE SATURACIÓN TRANSFERRINA | AB25: DIMERO-D | AU25: FOSFATASA ALCALINA | BK25: PROTEÍNAS TOTALES
A26: TRANSFERRINA | AB26: IDENTIFICACION DE INHIBIDORES | AU26: DESHIDROGENASA LACTICA (LDH) | BK26: HEMOGLOBINA GLICOSILADA (HBA1C) | BU26: X
A27: FERRITINA | AU27: ASPARTATO AMINOTRANSFERASA (AST/TGO) | BK27: CPK TOTAL
AU28: ALANINA AMINOTRANSFERASA (ALT/TGP) | BK28: FRUCTOSAMINA
A29: INMUNOLOGÍA / INFECCIOSAS | AU29: GAMMA-GLUTARIL TRANSFERASA (GGT) | BK29: PCR CUANTITATIVO
A30: COMPLEMENTO C3 | N30: ANTIGENO SUPERFICIE HEPATITIS B (HBSAG) | AB30: ORINA | AU30: AMILASA
A31: COMPLEMENTO C4 | N31: ANTICUERPOS ANTICORE Ig-G (HBcAG) | AB31: ELEMENTAL Y MICROSCOPICO (EMO) | AR31: X | AU31: LIPASA
A32: IgA TOTAL | N32: ANTICUERPOS ANTICORE Ig-M (HBcAG) | AB32: GRAM GOTA FRESCA | AU32: BILIRRUBINA TOTAL
A33: IgE TOTAL | N33: HEPATITIS C: HVC | AB33: OSMOLARIDAD URINARIA
A34: IgG TOTAL | N34: VIH (1+2) CUALITATIVA | AB34: SODIO EN ORINA PARCIAL | AU34: HECES
A35: IgM TOTAL | N35: VIH (1+2) CUANTITATIVA | AB35: POTASIO EN ORINA PARCIAL | AU35: COPROLÓGICO / COPROPARASITARIO | BK35: CRIPTOSPORIDIUM
A36: PROCALCITONINA | N36: HERPES 1 (IgG) | AB36: CLORO EN ORINA PARCIAL | AU36: COPROPARASITARIO POR CONCENTRACIÓN | BK36: OXIUROS
A37: IL-6 | N37: HERPES 1 (IgM) | AB37: CALCIO URINARIO | AU37: COPRO SERIADO | BK37: GARDIA-LAMBLIA ANTÍGENO
A38: ANA | N38: HERPES 2 (IgG) | AB38: FOSFORO EN ORINA PARCIAL | AU38: INVESTIGACION DE POLIMORFONUCLEARES (PMN) | BK38: INVESTIGACIÓN DE GRASAS
A39: ANCA-C | N39: HERPES 2 (IgM) | AB39: MAGNESIO EN ORINA PARCIAL | AU39: SANGRE OCULTA | BK39: AZÚCARES REDUCTORES
A40: ANCA-P | N40: RUBEOLA (IgG) | AB40: GLUCOSA EN ORINA PARCIAL | AU40: INVESTIGACIÓN DE pH | BK40: HELICOBACTER PYLORI
A41: ANTI-DNA | N41: RUBEOLA (IgM) | AB41: UREA EN ORINA PARCIAL | AU41: ROTAVIRUS
A42: ANTI-CCP | N42: TOXOPLASMA (IgG) | AB42: CREATINA EN ORINA PARCIAL | AU42: ADENOVIRIS
A43: ANTI-SM | N43: TOXOPLASMA (IgM) | AB43: NITRÓGENO UREICO EN ORINA PARCIAL
...

Sheet IMA012
A1: A. DATOS DEL ESTABLECIMIENTO Y USUARIO / PACIENTE
A2: INSTITUCIÓN DEL SISTEMA | P2: UNICÓDIGO | V2: ESTABLECIMIENTO DE SALUD | AN2: NÚMERO DE HISTORIA CLÍNICA ÚNICA | BF2: NÚMERO DE ARCHIVO
A3: =+HC!A3 -> RPC | P3: 56398 | V3: =+HC!T3 -> MEDISUPORT / QMC | AN3: =+HC!AH3 -> 1704289899
A4: PRIMER APELLIDO | P4: SEGUNDO APELLIDO | AC4: PRIMER NOMBRE | AP4: SEGUNDO NOMBRE | AZ4: SEXO | BC4: FECHA NACIMIENTO | BI4: EDAD | BL4: CONDICIÓN EDAD (MARCAR)
BL5: H | BN5: D | BP5: M | BR5: A
A6: =+HC!A5 -> AMENDAÑO | P6: =+HC!O5 -> COLLAGUAZO | AC6: =+HC!AC5 -> LUZ | AP6: =+HC!AQ5 -> EDELINA | AZ6: =+HC!BE5 -> F | BC6: =+HC!AZ3 -> 20346 | BI6: =+HC!BI5 -> 71 | BR6: X
A8: B. SERVICIO Y PRIORIDAD DE ATENCIÓN
A9: SERVICIO | Z9: ESPECIALIDAD | AQ9: CAMA | AW9: SALA | BC9: PRIORIDAD
A10: EMERGENCIA | H10: CONSULTA EXTERNA | O10: x | Q10: HOSPITALIZACIÓN | Z10: ENDOCRINOLOGIA | BC10: URGENTE | BI10: RUTINA | BN10: CONTROL | BR10: x
A12: C. ESTUDIO DE IMAGENOLOGÍA SOLICITADO
A13: RX CONVENCIONAL | I13: RX PORTÁTIL | O13: TOMOGRAFÍA | W13: RESONANCIA | AD13: ECOGRAFÍA | AK13: MAMOGRAFÍA | AS13: PROCEDIMIENTO | BB13: OTRO | BG13: SEDACIÓN | BL13: SI | BP13: NO | BR13: x
A14: DESCRIPCIÓN
A18: D. MOTIVO DE LA SOLICITUD | AO18: REGISTRAR LAS RAZONES PARA SOLICITAR EL ESTUDIO
A19: FUM (aaaa-mm-dd) | W19: PACIENTE CONTAMINADO | AK19: SI | AO19: NO | AQ19: x
A24: E. RESUMEN CLÍNICO ACTUAL | AC24: REGISTRAR DE MANERA OBLIGATORIA EL CUADRO CLÍNICO ACTUAL DEL PACIENTE
A25: =+HC!A24:BL24 -> 0
A28: F. DIAGNÓSTICO | T28: PRE= PRESUNTIVO DEF= DEFINITIVO | AC28: CIE | AG28: PRE | AI28: DEF | BL28: CIE | BP28: PRE | BR28: DEF
A29: 1. | B29: =IF(HC!B47=0," ",HC!B47) | AC29: =IF(HC!Y47=0," ",HC!Y47) | AG29: =IF(HC!AC47=0," ",HC!AC47) | AI29: =IF(HC!AE47=0," ",HC!AE47) | AK29: 4. | AL29: =IF(HC!AH47=0," ",HC!AH47) | BL29: =IF(HC!BE47=0," ",HC!BE47) | BP29: =IF(HC!BI47=0," ",HC!BI47) | BR29: =IF(HC!BK47=0," ",HC!BK47)
A30: 2. | B30: =IF(HC!B48=0," ",HC!B48) | AC30: =IF(HC!Y48=0," ",HC!Y48) | AG30: =IF(HC!AC48=0," ",HC!AC48) | AI30: =IF(HC!AE48=0," ",HC!AE48) | AK30: 5. | AL30: =IF(HC!AH48=0," ",HC!AH48) | BL30: =IF(HC!BE48=0," ",HC!BE48) | BP30: =IF(HC!BI48=0," ",HC!BI48) | BR30: =IF(HC!BK48=0," ",HC!BK48)
A31: 3. | B31: =IF(HC!B49=0," ",HC!B49) | AC31: =IF(HC!Y49=0," ",HC!Y49) | AG31: =IF(HC!AC49=0," ",HC!AC49) | AI31: =IF(HC!AE49=0," ",HC!AE49) | AK31: 6. | AL31: =IF(HC!AH49=0," ",HC!AH49) | BL31: =IF(HC!BE49=0," ",HC!BE49) | BP31: =IF(HC!BI49=0," ",HC!BI49) | BR31: =IF(HC!BK49=0," ",HC!BK49)
A33: G. DATOS DEL PROFESIONAL RESPONSABLE
A34: FECHA (aaaa-mm-dd) | I34: HORA (hh:mm) | P34: PRIMER NOMBRE | AK34: PRIMER APELLIDO | BD34: SEGUNDO APELLIDO
A35: =+TODAY() -> 46297 | I35: =+NOW() -> 46297.855 | P35: =+HC!O61 -> FRANK | AK35: =+HC!AH61 -> MEDINA | BD35: =+HC!AY61 -> ALI
A36: NÚMERO DE DOCUMENTO DE IDENTIFICACIÓN | P36: FIRMA | AP36: SELLO
A37: =+HC!A63 -> 1756930234
A39: SNS-MSP/HCU-form.012A/2021 | AG39: IMAGENOLOGÍA - SOLICITUD

Sheet RECETA
B3: MEDISUPORT INTERNATIONAL | E3: Ciudad: | F3: Quito | G3: Fecha | H3: =TODAY() -> 46297 | I3: RECETA Nº | J3: 0001
E4: DATOS DEL PACIENTE
E5: Nombre del paciente | G5: =+HC!A5 -> AMENDAÑO | H5: =+HC!O5 -> COLLAGUAZO | I5: =+HC!AC5 -> LUZ | J5: =+HC!AQ5 -> EDELINA
E6: H. CLINICA | F6: =+HC!AH3 -> 1704289899 | G6: CIE10 | H6: =CONCATENATE(HC!Y47,"/",HC!Y48) -> / | I6: CI/PASAPORTE | J6: =+HC!AH3 -> 1704289899
B7: RECETA DE MEDICAMENTOS | E7: Agudo | G7: Crónico
B8: Alergias: NO
B9: Nombre genérico o DCI, Concentración, Forma farmacéutica, Cantidad en números y letras | G9: DOSIS: | H9: FRECUENCIA: | I9: DURACIÓN: | J9: HORARIO
B19: DATOS DEL MÉDICO | E19: Espacio para el sello y firma del prescriptor (nombre, apellido, especialidad, libro, folio y número)
B20: Nombre | C20: DR. FRANK MEDINA | F20: Sello y firma
B21: Especialidad | C21: ENDOCRINOLOGIA
B22: Número | C22: =+HC!A63 -> 1756930234
B24: INDICACIONES | G24: RECETA Nº | H24: =J3 -> 0001
B25: Nombre paciente | D25: =CONCATENATE(G5," ",H5," ",I5," ",J5) -> AMENDAÑO COLLAGUAZO LUZ EDELINA | G25: FECHA | H25: =+H3 -> 46297
B26: Instrucciones para la administración del/los medicamentos | G26: DOSIS: | H26: FRECUENCIA: | I26: DURACIÓN: | J26: HORARIO
B27: =+B10 -> 0 | G27: =G10 -> 0 | H27: =H10 -> 0 | I27: =I10 -> 0 | J27: =J10 -> 0
B28: =+B11 -> 0 | G28: =G11 -> 0 | H28: =H11 -> 0 | I28: =I11 -> 0 | J28: =J11 -> 0
B29: =+B12 -> 0 | G29: =G12 -> 0 | H29: =H12 -> 0 | I29: =I12 -> 0 | J29: =J12 -> 0
B30: =+B13 -> 0 | G30: =G13 -> 0 | H30: =H13 -> 0 | I30: =I13 -> 0 | J30: =J13 -> 0
B31: =+B14 -> 0 | G31: =G14 -> 0 | H31: =H14 -> 0 | I31: =I14 -> 0 | J31: =J14 -> 0
B32: =+B15 -> 0 | G32: =G15 -> 0 | H32: =H15 -> 0 | I32: =I15 -> 0 | J32: =J15 -> 0
G33: =G16 -> 0 | H33: =H16 -> 0 | I33: =I16 -> 0 | J33: =J16 -> 0
G34: =G17 -> 0 | H34: =H17 -> 0 | I34: =I17 -> 0 | J34: =J17 -> 0
B35: ADVERTENCIAS:
B36: DATOS DEL MÉDICO | E36: Espacio para el sello y firma del prescriptor (nombre, apellido, especialidad, libro, folio y número)
B37: Nombre | C37: =+C20 -> DR. FRANK MEDINA | F37: Sello y firma
B38: Especialidad | C38: =+C21 -> ENDOCRINOLOGIA
B39: Número | C39: =+C22 -> 1756930234
